Workbook

Sheet README
A1: Club Rio Jake — Draft Order vs. Results, 2011-2025
A2: Yahoo Fantasy Football league #183003 (custom URL: clubriojake)
A5: WHAT THIS WORKBOOK ANSWERS
B6: Does where you pick in the draft predict how your season goes — in regular-season record, in total points scored, and in the playoffs?
A8: TABS
A9: All Seasons | B9: The single source of truth: 180 rows = 15 seasons x 12 teams. Every other tab reads from here by formula.
A10: Season 2011 ... Season 2025 | B10: One tab per season, sorted by that season's draft slot (1st overall pick down to 12th).
A11: By Draft Slot | B11: All 15 seasons pooled and averaged by draft slot 1-12.
A12: Correlations | B12: Correlation between draft slot and each outcome, per season and overall.
A13: Playoff Grid | B13: Which draft slot finished 1st, 2nd, 3rd ... each season, plus championship counts by slot.
A15: HOW TO READ THE KEY COLUMNS
A16: Draft Slot | B16: Position in round 1 of that season's snake draft. 1 = first overall pick. Taken from Yahoo's Draft Results page (round 1 order).
A17: Win % | B17: (W + 0.5*T) / games played. Normalised because the league played 13 regular-season games 2011-2020 and 14 games 2021-2025.
A18: Points For | B18: Regular-season points scored, as shown in Yahoo's standings (PF column). Yahoo reports whole numbers for 2011-2018 and two decimals from 2019 on.
A19: Pts/Game | B19: Points For / games played. Use this rather than raw Points For when comparing across seasons.
A20: PF Rank | B20: Rank within that season by points scored, 1 = most points in the league that year.
A21: Final Finish | B21: Yahoo's end-of-season rank after the playoff and consolation brackets. 1 = league champion.
A22: Made Playoffs | B22: 1 = qualified. The league has used a 12-team / 6-playoff-spot format in all 15 seasons, so Final Finish 1-6 is exactly the playoff field.
A24: IMPORTANT NOTES AND ASSUMPTIONS
A25: Team names change | B25: Managers rename teams between seasons. The Manager column is the constant — use it, not Team, to follow a franchise through time. Example: Cory = Big Red Machine (2011-17), Mean Machine (2018), Fournetflix n Chill (2019), Dark Shadows (2020-21), Fighting Mickeys (2022), Broken Rhules (2023-25).
A26: One roster handoff | B26: The name 'PappyVanDrinkle' belonged to Keith in 2023 and to Jace in 2024 — Yahoo carried the team name over to a new manager. Treated as two different franchises.
A27: Season length | B27: 13 regular-season games 2011-2020; 14 games 2021-2025. Divisions also changed (3 divisions of 4, then 4 divisions of 3, then back).
A28: Correlation sign | B28: Win %, Points For and Pts/Game: a NEGATIVE correlation with draft slot means earlier picks did better. PF Rank and Final Finish are themselves ranks where 1 is best, so a POSITIVE correlation means earlier picks did better.
A29: Small samples | B29: 15 observations per draft slot. Treat per-slot splits as trivia unless the correlation tab shows a low p-value; single-slot records swing hard on one or two seasons.
A31: SOURCE | B31: Yahoo Fantasy Football league pages, read directly from the league's own history: Standings tab (record / PF / final rank), Draft Results page (round 1 order), Managers page (team-to-manager mapping). Retrieved 13 Aug 2026.

Sheet All Seasons
A1: Season | B1: Draft Slot | C1: Team | D1: Manager | E1: W | F1: L | G1: T | H1: Games | I1: Record | J1: Win % | K1: Points For | L1: Pts/Game | M1: PF Rank | N1: Final Finish | O1: Made Playoffs | P1: Champion | Q1: Made Final | R1: Top-3 Finish
A2: 2011 | B2: 1 | C2: Going Postal | D2: Steve | E2: 6 | F2: 7 | G2: 0 | H2: 13 | I2: =E2&"-"&F2&"-"&G2 -> 6-7-0 | J2: =(E2+0.5*G2)/H2 -> 0.46153846 | K2: 1299 | L2: =K2/H2 -> 99.923077 | M2: =SUMPRODUCT(($A$2:$A$181=A2)*($K$2:$K$181>K2))+1 -> 6 | N2: 1 | O2: =IF(N2<=6,1,0) -> 1 | P2: =IF(N2=1,1,0) -> 1 | Q2: =IF(N2<=2,1,0) -> 1 | R2: =IF(N2<=3,1,0) -> 1
A3: 2011 | B3: 2 | C3: Scott's Scabs | D3: Scott | E3: 11 | F3: 2 | G3: 0 | H3: 13 | I3: =E3&"-"&F3&"-"&G3 -> 11-2-0 | J3: =(E3+0.5*G3)/H3 -> 0.84615385 | K3: 1480 | L3: =K3/H3 -> 113.84615 | M3: =SUMPRODUCT(($A$2:$A$181=A3)*($K$2:$K$181>K3))+1 -> 3 | N3: 2 | O3: =IF(N3<=6,1,0) -> 1 | P3: =IF(N3=1,1,0) -> 0 | Q3: =IF(N3<=2,1,0) -> 1 | R3: =IF(N3<=3,1,0) -> 1
A4: 2011 | B4: 3 | C4: RedNecks | D4: Jim | E4: 6 | F4: 7 | G4: 0 | H4: 13 | I4: =E4&"-"&F4&"-"&G4 -> 6-7-0 | J4: =(E4+0.5*G4)/H4 -> 0.46153846 | K4: 1231 | L4: =K4/H4 -> 94.692308 | M4: =SUMPRODUCT(($A$2:$A$181=A4)*($K$2:$K$181>K4))+1 -> 8 | N4: 10 | O4: =IF(N4<=6,1,0) -> 0 | P4: =IF(N4=1,1,0) -> 0 | Q4: =IF(N4<=2,1,0) -> 0 | R4: =IF(N4<=3,1,0) -> 0
A5: 2011 | B5: 4 | C5: Big Red Machine | D5: Cory | E5: 9 | F5: 4 | G5: 0 | H5: 13 | I5: =E5&"-"&F5&"-"&G5 -> 9-4-0 | J5: =(E5+0.5*G5)/H5 -> 0.69230769 | K5: 1608 | L5: =K5/H5 -> 123.69231 | M5: =SUMPRODUCT(($A$2:$A$181=A5)*($K$2:$K$181>K5))+1 -> 2 | N5: 4 | O5: =IF(N5<=6,1,0) -> 1 | P5: =IF(N5=1,1,0) -> 0 | Q5: =IF(N5<=2,1,0) -> 0 | R5: =IF(N5<=3,1,0) -> 0
A6: 2011 | B6: 5 | C6: RedZone480 | D6: Robert | E6: 12 | F6: 1 | G6: 0 | H6: 13 | I6: =E6&"-"&F6&"-"&G6 -> 12-1-0 | J6: =(E6+0.5*G6)/H6 -> 0.92307692 | K6: 1670 | L6: =K6/H6 -> 128.46154 | M6: =SUMPRODUCT(($A$2:$A$181=A6)*($K$2:$K$181>K6))+1 -> 1 | N6: 3 | O6: =IF(N6<=6,1,0) -> 1 | P6: =IF(N6=1,1,0) -> 0 | Q6: =IF(N6<=2,1,0) -> 0 | R6: =IF(N6<=3,1,0) -> 1
A7: 2011 | B7: 6 | C7: Donkey Punchers | D7: Barrett | E7: 4 | F7: 9 | G7: 0 | H7: 13 | I7: =E7&"-"&F7&"-"&G7 -> 4-9-0 | J7: =(E7+0.5*G7)/H7 -> 0.30769231 | K7: 1187 | L7: =K7/H7 -> 91.307692 | M7: =SUMPRODUCT(($A$2:$A$181=A7)*($K$2:$K$181>K7))+1 -> 11 | N7: 12 | O7: =IF(N7<=6,1,0) -> 0 | P7: =IF(N7=1,1,0) -> 0 | Q7: =IF(N7<=2,1,0) -> 0 | R7: =IF(N7<=3,1,0) -> 0
A8: 2011 | B8: 7 | C8: Closer | D8: Rick | E8: 1 | F8: 12 | G8: 0 | H8: 13 | I8: =E8&"-"&F8&"-"&G8 -> 1-12-0 | J8: =(E8+0.5*G8)/H8 -> 0.076923077 | K8: 1076 | L8: =K8/H8 -> 82.769231 | M8: =SUMPRODUCT(($A$2:$A$181=A8)*($K$2:$K$181>K8))+1 -> 12 | N8: 9 | O8: =IF(N8<=6,1,0) -> 0 | P8: =IF(N8=1,1,0) -> 0 | Q8: =IF(N8<=2,1,0) -> 0 | R8: =IF(N8<=3,1,0) -> 0
A9: 2011 | B9: 8 | C9: MochaMessiahMadeMe$$ | D9: Keith | E9: 4 | F9: 9 | G9: 0 | H9: 13 | I9: =E9&"-"&F9&"-"&G9 -> 4-9-0 | J9: =(E9+0.5*G9)/H9 -> 0.30769231 | K9: 1322 | L9: =K9/H9 -> 101.69231 | M9: =SUMPRODUCT(($A$2:$A$181=A9)*($K$2:$K$181>K9))+1 -> 5 | N9: 7 | O9: =IF(N9<=6,1,0) -> 0 | P9: =IF(N9=1,1,0) -> 0 | Q9: =IF(N9<=2,1,0) -> 0 | R9: =IF(N9<=3,1,0) -> 0
A10: 2011 | B10: 9 | C10: Vandalay Industries | D10: John | E10: 6 | F10: 7 | G10: 0 | H10: 13 | I10: =E10&"-"&F10&"-"&G10 -> 6-7-0 | J10: =(E10+0.5*G10)/H10 -> 0.46153846 | K10: 1331 | L10: =K10/H10 -> 102.38462 | M10: =SUMPRODUCT(($A$2:$A$181=A10)*($K$2:$K$181>K10))+1 -> 4 | N10: 6 | O10: =IF(N10<=6,1,0) -> 1 | P10: =IF(N10=1,1,0) -> 0 | Q10: =IF(N10<=2,1,0) -> 0 | R10: =IF(N10<=3,1,0) -> 0
A11: 2011 | B11: 10 | C11: AssKickers | D11: Rob M | E11: 6 | F11: 7 | G11: 0 | H11: 13 | I11: =E11&"-"&F11&"-"&G11 -> 6-7-0 | J11: =(E11+0.5*G11)/H11 -> 0.46153846 | K11: 1225 | L11: =K11/H11 -> 94.230769 | M11: =SUMPRODUCT(($A$2:$A$181=A11)*($K$2:$K$181>K11))+1 -> 9 | N11: 11 | O11: =IF(N11<=6,1,0) -> 0 | P11: =IF(N11=1,1,0) -> 0 | Q11: =IF(N11<=2,1,0) -> 0 | R11: =IF(N11<=3,1,0) -> 0
A12: 2011 | B12: 11 | C12: Crackerman | D12: Michael M | E12: 6 | F12: 7 | G12: 0 | H12: 13 | I12: =E12&"-"&F12&"-"&G12 -> 6-7-0 | J12: =(E12+0.5*G12)/H12 -> 0.46153846 | K12: 1271 | L12: =K12/H12 -> 97.769231 | M12: =SUMPRODUCT(($A$2:$A$181=A12)*($K$2:$K$181>K12))+1 -> 7 | N12: 8 | O12: =IF(N12<=6,1,0) -> 0 | P12: =IF(N12=1,1,0) -> 0 | Q12: =IF(N12<=2,1,0) -> 0 | R12: =IF(N12<=3,1,0) -> 0
A13: 2011 | B13: 12 | C13: Spike's Chupacabras | D13: Spike | E13: 7 | F13: 6 | G13: 0 | H13: 13 | I13: =E13&"-"&F13&"-"&G13 -> 7-6-0 | J13: =(E13+0.5*G13)/H13 -> 0.53846154 | K13: 1206 | L13: =K13/H13 -> 92.769231 | M13: =SUMPRODUCT(($A$2:$A$181=A13)*($K$2:$K$181>K13))+1 -> 10 | N13: 5 | O13: =IF(N13<=6,1,0) -> 1 | P13: =IF(N13=1,1,0) -> 0 | Q13: =IF(N13<=2,1,0) -> 0 | R13: =IF(N13<=3,1,0) -> 0
... A181: 2025 | B181: 12 | C181: RedZone480 | D181: Robert | E181: 8 | F181: 6 | G181: 0 | H181: 14 | I181: =E181&"-"&F181&"-"&G181 -> 8-6-0 | J181: =(E181+0.5*G181)/H181 -> 0.57142857 | K181: 1494.82 | L181: =K181/H181 -> 106.77286 | M181: =SUMPRODUCT(($A$2:$A$181=A181)*($K$2:$K$181>K181))+1 -> 6 | N181: 5 | O181: =IF(N181<=6,1,0) -> 1 | P181: =IF(N181=1,1,0) -> 0 | Q181: =IF(N181<=2,1,0) -> 0 | R181: =IF(N181<=3,1,0) -> 0

Sheet Season 2011
A1: 2011 season — ordered by draft slot
A2: 13-game regular season · 12 teams · 6 playoff spots · pick 1 = first overall
A4: Draft Slot | B4: Team | C4: Manager | D4: Record | E4: Win % | F4: Points For | G4: Pts/Game | H4: PF Rank | I4: Final Finish | J4: Made Playoffs?
A5: ='All Seasons'!B2 -> 1 | B5: ='All Seasons'!C2 -> Going Postal | C5: ='All Seasons'!D2 -> Steve | D5: ='All Seasons'!I2 -> 6-7-0 | E5: ='All Seasons'!J2 -> 0.46153846 | F5: ='All Seasons'!K2 -> 1299 | G5: ='All Seasons'!L2 -> 99.923077 | H5: ='All Seasons'!M2 -> 6 | I5: ='All Seasons'!N2 -> 1 | J5: =IF('All Seasons'!O2=1,"YES","-") -> YES
A6: ='All Seasons'!B3 -> 2 | B6: ='All Seasons'!C3 -> Scott's Scabs | C6: ='All Seasons'!D3 -> Scott | D6: ='All Seasons'!I3 -> 11-2-0 | E6: ='All Seasons'!J3 -> 0.84615385 | F6: ='All Seasons'!K3 -> 1480 | G6: ='All Seasons'!L3 -> 113.84615 | H6: ='All Seasons'!M3 -> 3 | I6: ='All Seasons'!N3 -> 2 | J6: =IF('All Seasons'!O3=1,"YES","-") -> YES
A7: ='All Seasons'!B4 -> 3 | B7: ='All Seasons'!C4 -> RedNecks | C7: ='All Seasons'!D4 -> Jim | D7: ='All Seasons'!I4 -> 6-7-0 | E7: ='All Seasons'!J4 -> 0.46153846 | F7: ='All Seasons'!K4 -> 1231 | G7: ='All Seasons'!L4 -> 94.692308 | H7: ='All Seasons'!M4 -> 8 | I7: ='All Seasons'!N4 -> 10 | J7: =IF('All Seasons'!O4=1,"YES","-") -> -
A8: ='All Seasons'!B5 -> 4 | B8: ='All Seasons'!C5 -> Big Red Machine | C8: ='All Seasons'!D5 -> Cory | D8: ='All Seasons'!I5 -> 9-4-0 | E8: ='All Seasons'!J5 -> 0.69230769 | F8: ='All Seasons'!K5 -> 1608 | G8: ='All Seasons'!L5 -> 123.69231 | H8: ='All Seasons'!M5 -> 2 | I8: ='All Seasons'!N5 -> 4 | J8: =IF('All Seasons'!O5=1,"YES","-") -> YES
A9: ='All Seasons'!B6 -> 5 | B9: ='All Seasons'!C6 -> RedZone480 | C9: ='All Seasons'!D6 -> Robert | D9: ='All Seasons'!I6 -> 12-1-0 | E9: ='All Seasons'!J6 -> 0.92307692 | F9: ='All Seasons'!K6 -> 1670 | G9: ='All Seasons'!L6 -> 128.46154 | H9: ='All Seasons'!M6 -> 1 | I9: ='All Seasons'!N6 -> 3 | J9: =IF('All Seasons'!O6=1,"YES","-") -> YES
A10: ='All Seasons'!B7 -> 6 | B10: ='All Seasons'!C7 -> Donkey Punchers | C10: ='All Seasons'!D7 -> Barrett | D10: ='All Seasons'!I7 -> 4-9-0 | E10: ='All Seasons'!J7 -> 0.30769231 | F10: ='All Seasons'!K7 -> 1187 | G10: ='All Seasons'!L7 -> 91.307692 | H10: ='All Seasons'!M7 -> 11 | I10: ='All Seasons'!N7 -> 12 | J10: =IF('All Seasons'!O7=1,"YES","-") -> -
A11: ='All Seasons'!B8 -> 7 | B11: ='All Seasons'!C8 -> Closer | C11: ='All Seasons'!D8 -> Rick | D11: ='All Seasons'!I8 -> 1-12-0 | E11: ='All Seasons'!J8 -> 0.076923077 | F11: ='All Seasons'!K8 -> 1076 | G11: ='All Seasons'!L8 -> 82.769231 | H11: ='All Seasons'!M8 -> 12 | I11: ='All Seasons'!N8 -> 9 | J11: =IF('All Seasons'!O8=1,"YES","-") -> -
A12: ='All Seasons'!B9 -> 8 | B12: ='All Seasons'!C9 -> MochaMessiahMadeMe$$ | C12: ='All Seasons'!D9 -> Keith | D12: ='All Seasons'!I9 -> 4-9-0 | E12: ='All Seasons'!J9 -> 0.30769231 | F12: ='All Seasons'!K9 -> 1322 | G12: ='All Seasons'!L9 -> 101.69231 | H12: ='All Seasons'!M9 -> 5 | I12: ='All Seasons'!N9 -> 7 | J12: =IF('All Seasons'!O9=1,"YES","-") -> -
A13: ='All Seasons'!B10 -> 9 | B13: ='All Seasons'!C10 -> Vandalay Industries | C13: ='All Seasons'!D10 -> John | D13: ='All Seasons'!I10 -> 6-7-0 | E13: ='All Seasons'!J10 -> 0.46153846 | F13: ='All Seasons'!K10 -> 1331 | G13: ='All Seasons'!L10 -> 102.38462 | H13: ='All Seasons'!M10 -> 4 | I13: ='All Seasons'!N10 -> 6 | J13: =IF('All Seasons'!O10=1,"YES","-") -> YES
A14: ='All Seasons'!B11 -> 10 | B14: ='All Seasons'!C11 -> AssKickers | C14: ='All Seasons'!D11 -> Rob M | D14: ='All Seasons'!I11 -> 6-7-0 | E14: ='All Seasons'!J11 -> 0.46153846 | F14: ='All Seasons'!K11 -> 1225 | G14: ='All Seasons'!L11 -> 94.230769 | H14: ='All Seasons'!M11 -> 9 | I14: ='All Seasons'!N11 -> 11 | J14: =IF('All Seasons'!O11=1,"YES","-") -> -
A15: ='All Seasons'!B12 -> 11 | B15: ='All Seasons'!C12 -> Crackerman | C15: ='All Seasons'!D12 -> Michael M | D15: ='All Seasons'!I12 -> 6-7-0 | E15: ='All Seasons'!J12 -> 0.46153846 | F15: ='All Seasons'!K12 -> 1271 | G15: ='All Seasons'!L12 -> 97.769231 | H15: ='All Seasons'!M12 -> 7 | I15: ='All Seasons'!N12 -> 8 | J15: =IF('All Seasons'!O12=1,"YES","-") -> -
A16: ='All Seasons'!B13 -> 12 | B16: ='All Seasons'!C13 -> Spike's Chupacabras | C16: ='All Seasons'!D13 -> Spike | D16: ='All Seasons'!I13 -> 7-6-0 | E16: ='All Seasons'!J13 -> 0.53846154 | F16: ='All Seasons'!K13 -> 1206 | G16: ='All Seasons'!L13 -> 92.769231 | H16: ='All Seasons'!M13 -> 10 | I16: ='All Seasons'!N13 -> 5 | J16: =IF('All Seasons'!O13=1,"YES","-") -> YES
B17: League total / average | E17: =AVERAGE(E5:E16) -> 0.5 | F17: =SUM(F5:F16) -> 15906 | G17: =AVERAGE(G5:G16) -> 101.96154
A19: Correlation with draft slot (this season)
A20: Win % | C20: =CORREL($A$5:$A$16,E5:E16) -> -0.31619492
A21: Pts/Game | C21: =CORREL($A$5:$A$16,G5:G16) -> -0.39291485
A22: PF Rank (1=most pts) | C22: =CORREL($A$5:$A$16,H5:H16) -> 0.38461538
A23: Final Finish (1=champ) | C23: =CORREL($A$5:$A$16,I5:I16) -> 0.43356643
A24: Negative on Win % / Pts-Game = earlier picks did better. Positive on PF Rank / Final Finish = earlier picks did better.

Sheet Season 2012
A1: 2012 season — ordered by draft slot
A2: 13-game regular season · 12 teams · 6 playoff spots · pick 1 = first overall
A4: Draft Slot | B4: Team | C4: Manager | D4: Record | E4: Win % | F4: Points For | G4: Pts/Game | H4: PF Rank | I4: Final Finish | J4: Made Playoffs?
A5: ='All Seasons'!B14 -> 1 | B5: ='All Seasons'!C14 -> Crackerman | C5: ='All Seasons'!D14 -> Michael M | D5: ='All Seasons'!I14 -> 3-10-0 | E5: ='All Seasons'!J14 -> 0.23076923 | F5: ='All Seasons'!K14 -> 1309 | G5: ='All Seasons'!L14 -> 100.69231 | H5: ='All Seasons'!M14 -> 7 | I5: ='All Seasons'!N14 -> 11 | J5: =IF('All Seasons'!O14=1,"YES","-") -> -
A6: ='All Seasons'!B15 -> 2 | B6: ='All Seasons'!C15 -> Spike's Chupacabras | C6: ='All Seasons'!D15 -> Spike | D6: ='All Seasons'!I15 -> 5-8-0 | E6: ='All Seasons'!J15 -> 0.38461538 | F6: ='All Seasons'!K15 -> 1368 | G6: ='All Seasons'!L15 -> 105.23077 | H6: ='All Seasons'!M15 -> 4 | I6: ='All Seasons'!N15 -> 10 | J6: =IF('All Seasons'!O15=1,"YES","-") -> -
A7: ='All Seasons'!B16 -> 3 | B7: ='All Seasons'!C16 -> AssKickers | C7: ='All Seasons'!D16 -> Rob M | D7: ='All Seasons'!I16 -> 7-6-0 | E7: ='All Seasons'!J16 -> 0.53846154 | F7: ='All Seasons'!K16 -> 1321 | G7: ='All Seasons'!L16 -> 101.61538 | H7: ='All Seasons'!M16 -> 6 | I7: ='All Seasons'!N16 -> 4 | J7: =IF('All Seasons'!O16=1,"YES","-") -> YES
A8: ='All Seasons'!B17 -> 4 | B8: ='All Seasons'!C17 -> Donkey Punchers | C8: ='All Seasons'!D17 -> Barrett | D8: ='All Seasons'!I17 -> 5-8-0 | E8: ='All Seasons'!J17 -> 0.38461538 | F8: ='All Seasons'!K17 -> 1234 | G8: ='All Seasons'!L17 -> 94.923077 | H8: ='All Seasons'!M17 -> 11 | I8: ='All Seasons'!N17 -> 9 | J8: =IF('All Seasons'!O17=1,"YES","-") -> -
A9: ='All Seasons'!B18 -> 5 | B9: ='All Seasons'!C18 -> Big Red Machine | C9: ='All Seasons'!D18 -> Cory | D9: ='All Seasons'!I18 -> 5-8-0 | E9: ='All Seasons'!J18 -> 0.38461538 | F9: ='All Seasons'!K18 -> 1297 | G9: ='All Seasons'!L18 -> 99.769231 | H9: ='All Seasons'!M18 -> 9 | I9: ='All Seasons'!N18 -> 7 | J9: =IF('All Seasons'!O18=1,"YES","-") -> -
A10: ='All Seasons'!B19 -> 6 | B10: ='All Seasons'!C19 -> MochaMessiahMadeMe$$ | C10: ='All Seasons'!D19 -> Keith | D10: ='All Seasons'!I19 -> 9-4-0 | E10: ='All Seasons'!J19 -> 0.69230769 | F10: ='All Seasons'!K19 -> 1357 | G10: ='All Seasons'!L19 -> 104.38462 | H10: ='All Seasons'!M19 -> 5 | I10: ='All Seasons'!N19 -> 1 | J10: =IF('All Seasons'!O19=1,"YES","-") -> YES
A11: ='All Seasons'!B20 -> 7 | B11: ='All Seasons'!C20 -> Closer | C11: ='All Seasons'!D20 -> Rick | D11: ='All Seasons'!I20 -> 5-8-0 | E11: ='All Seasons'!J20 -> 0.38461538 | F11: ='All Seasons'!K20 -> 1276 | G11: ='All Seasons'!L20 -> 98.153846 | H11: ='All Seasons'!M20 -> 10 | I11: ='All Seasons'!N20 -> 12 | J11: =IF('All Seasons'!O20=1,"YES","-") -> -
A12: ='All Seasons'!B21 -> 8 | B12: ='All Seasons'!C21 -> Vandalay Industries | C12: ='All Seasons'!D21 -> John | D12: ='All Seasons'!I21 -> 7-6-0 | E12: ='All Seasons'!J21 -> 0.53846154 | F12: ='All Seasons'!K21 -> 1417 | G12: ='All Seasons'!L21 -> 109 | H12: ='All Seasons'!M21 -> 3 | I12: ='All Seasons'!N21 -> 3 | J12: =IF('All Seasons'!O21=1,"YES","-") -> YES
A13: ='All Seasons'!B22 -> 9 | B13: ='All Seasons'!C22 -> Scott's Scabs | C13: ='All Seasons'!D22 -> Scott | D13: ='All Seasons'!I22 -> 8-5-0 | E13: ='All Seasons'!J22 -> 0.61538462 | F13: ='All Seasons'!K22 -> 1302 | G13: ='All Seasons'!L22 -> 100.15385 | H13: ='All Seasons'!M22 -> 8 | I13: ='All Seasons'!N22 -> 6 | J13: =IF('All Seasons'!O22=1,"YES","-") -> YES
A14: ='All Seasons'!B23 -> 10 | B14: ='All Seasons'!C23 -> RedZone480 | C14: ='All Seasons'!D23 -> Robert | D14: ='All Seasons'!I23 -> 10-3-0 | E14: ='All Seasons'!J23 -> 0.76923077 | F14: ='All Seasons'!K23 -> 1458 | G14: ='All Seasons'!L23 -> 112.15385 | H14: ='All Seasons'!M23 -> 1 | I14: ='All Seasons'!N23 -> 2 | J14: =IF('All Seasons'!O23=1,"YES","-") -> YES
A15: ='All Seasons'!B24 -> 11 | B15: ='All Seasons'!C24 -> Going Postal | C15: ='All Seasons'!D24 -> Steve | D15: ='All Seasons'!I24 -> 6-7-0 | E15: ='All Seasons'!J24 -> 0.46153846 | F15: ='All Seasons'!K24 -> 1455 | G15: ='All Seasons'!L24 -> 111.92308 | H15: ='All Seasons'!M24 -> 2 | I15: ='All Seasons'!N24 -> 8 | J15: =IF('All Seasons'!O24=1,"YES","-") -> -
A16: ='All Seasons'!B25 -> 12 | B16: ='All Seasons'!C25 -> RedNecks | C16: ='All Seasons'!D25 -> Jim | D16: ='All Seasons'!I25 -> 8-5-0 | E16: ='All Seasons'!J25 -> 0.61538462 | F16: ='All Seasons'!K25 -> 1220 | G16: ='All Seasons'!L25 -> 93.846154 | H16: ='All Seasons'!M25 -> 12 | I16: ='All Seasons'!N25 -> 5 | J16: =IF('All Seasons'!O25=1,"YES","-") -> YES
B17: League total / average | E17: =AVERAGE(E5:E16) -> 0.5 | F17: =SUM(F5:F16) -> 16014 | G17: =AVERAGE(G5:G16) -> 102.65385
A19: Correlation with draft slot (this season)
A20: Win % | C20: =CORREL($A$5:$A$16,E5:E16) -> 0.63576395
A21: Pts/Game | C21: =CORREL($A$5:$A$16,G5:G16) -> 0.22137313
A22: PF Rank (1=most pts) | C22: =CORREL($A$5:$A$16,H5:H16) -> -0.090909091
A23: Final Finish (1=champ) | C23: =CORREL($A$5:$A$16,I5:I16) -> -0.3986014
A24: Negative on Win % / Pts-Game = earlier picks did better. Positive on PF Rank / Final Finish = earlier picks did better.

Sheet Season 2013
A1: 2013 season — ordered by draft slot
A2: 13-game regular season · 12 teams · 6 playoff spots · pick 1 = first overall
A4: Draft Slot | B4: Team | C4: Manager | D4: Record | E4: Win % | F4: Points For | G4: Pts/Game | H4: PF Rank | I4: Final Finish | J4: Made Playoffs?
A5: ='All Seasons'!B26 -> 1 | B5: ='All Seasons'!C26 -> Going Postal | C5: ='All Seasons'!D26 -> Steve | D5: ='All Seasons'!I26 -> 7-6-0 | E5: ='All Seasons'!J26 -> 0.53846154 | F5: ='All Seasons'!K26 -> 1272 | G5: ='All Seasons'!L26 -> 97.846154 | H5: ='All Seasons'!M26 -> 11 | I5: ='All Seasons'!N26 -> 9 | J5: =IF('All Seasons'!O26=1,"YES","-") -> -
A6: ='All Seasons'!B27 -> 2 | B6: ='All Seasons'!C27 -> Vandalay Industries | C6: ='All Seasons'!D27 -> John | D6: ='All Seasons'!I27 -> 9-4-0 | E6: ='All Seasons'!J27 -> 0.69230769 | F6: ='All Seasons'!K27 -> 1449 | G6: ='All Seasons'!L27 -> 111.46154 | H6: ='All Seasons'!M27 -> 3 | I6: ='All Seasons'!N27 -> 2 | J6: =IF('All Seasons'!O27=1,"YES","-") -> YES
A7: ='All Seasons'!B28 -> 3 | B7: ='All Seasons'!C28 -> Donkey Punchers | C7: ='All Seasons'!D28 -> Barrett | D7: ='All Seasons'!I28 -> 4-9-0 | E7: ='All Seasons'!J28 -> 0.30769231 | F7: ='All Seasons'!K28 -> 1297 | G7: ='All Seasons'!L28 -> 99.769231 | H7: ='All Seasons'!M28 -> 10 | I7: ='All Seasons'!N28 -> 8 | J7: =IF('All Seasons'!O28=1,"YES","-") -> -
A8: ='All Seasons'!B29 -> 4 | B8: ='All Seasons'!C29 -> Big Red Machine | C8: ='All Seasons'!D29 -> Cory | D8: ='All Seasons'!I29 -> 8-5-0 | E8: ='All Seasons'!J29 -> 0.61538462 | F8: ='All Seasons'!K29 -> 1523 | G8: ='All Seasons'!L29 -> 117.15385 | H8: ='All Seasons'!M29 -> 2 | I8: ='All Seasons'!N29 -> 1 | J8: =IF('All Seasons'!O29=1,"YES","-") -> YES
A9: ='All Seasons'!B30 -> 5 | B9: ='All Seasons'!C30 -> AssKickers | C9: ='All Seasons'!D30 -> Rob M | D9: ='All Seasons'!I30 -> 7-6-0 | E9: ='All Seasons'!J30 -> 0.53846154 | F9: ='All Seasons'!K30 -> 1298 | G9: ='All Seasons'!L30 -> 99.846154 | H9: ='All Seasons'!M30 -> 9 | I9: ='All Seasons'!N30 -> 10 | J9: =IF('All Seasons'!O30=1,"YES","-") -> -
A10: ='All Seasons'!B31 -> 6 | B10: ='All Seasons'!C31 -> CreepyAssCrackers | C10: ='All Seasons'!D31 -> Keith | D10: ='All Seasons'!I31 -> 10-3-0 | E10: ='All Seasons'!J31 -> 0.76923077 | F10: ='All Seasons'!K31 -> 1396 | G10: ='All Seasons'!L31 -> 107.38462 | H10: ='All Seasons'!M31 -> 4 | I10: ='All Seasons'!N31 -> 4 | J10: =IF('All Seasons'!O31=1,"YES","-") -> YES
A11: ='All Seasons'!B32 -> 7 | B11: ='All Seasons'!C32 -> Crackerman | C11: ='All Seasons'!D32 -> Michael M | D11: ='All Seasons'!I32 -> 4-9-0 | E11: ='All Seasons'!J32 -> 0.30769231 | F11: ='All Seasons'!K32 -> 1208 | G11: ='All Seasons'!L32 -> 92.923077 | H11: ='All Seasons'!M32 -> 12 | I11: ='All Seasons'!N32 -> 11 | J11: =IF('All Seasons'!O32=1,"YES","-") -> -
A12: ='All Seasons'!B33 -> 8 | B12: ='All Seasons'!C33 -> RedNecks | C12: ='All Seasons'!D33 -> Jim | D12: ='All Seasons'!I33 -> 4-9-0 | E12: ='All Seasons'!J33 -> 0.30769231 | F12: ='All Seasons'!K33 -> 1351 | G12: ='All Seasons'!L33 -> 103.92308 | H12: ='All Seasons'!M33 -> 5 | I12: ='All Seasons'!N33 -> 7 | J12: =IF('All Seasons'!O33=1,"YES","-") -> -
A13: ='All Seasons'!B34 -> 9 | B13: ='All Seasons'!C34 -> Spike's Chupacabras | C13: ='All Seasons'!D34 -> Spike | D13: ='All Seasons'!I34 -> 7-6-0 | E13: ='All Seasons'!J34 -> 0.53846154 | F13: ='All Seasons'!K34 -> 1325 | G13: ='All Seasons'!L34 -> 101.92308 | H13: ='All Seasons'!M34 -> 6 | I13: ='All Seasons'!N34 -> 6 | J13: =IF('All Seasons'!O34=1,"YES","-") -> YES
A14: ='All Seasons'!B35 -> 10 | B14: ='All Seasons'!C35 -> RedZone480 | C14: ='All Seasons'!D35 -> Robert | D14: ='All Seasons'!I35 -> 9-4-0 | E14: ='All Seasons'!J35 -> 0.69230769 | F14: ='All Seasons'!K35 -> 1704 | G14: ='All Seasons'!L35 -> 131.07692 | H14: ='All Seasons'!M35 -> 1 | I14: ='All Seasons'!N35 -> 3 | J14: =IF('All Seasons'!O35=1,"YES","-") -> YES
A15: ='All Seasons'!B36 -> 11 | B15: ='All Seasons'!C36 -> Closer | C15: ='All Seasons'!D36 -> Rick | D15: ='All Seasons'!I36 -> 7-6-0 | E15: ='All Seasons'!J36 -> 0.53846154 | F15: ='All Seasons'!K36 -> 1310 | G15: ='All Seasons'!L36 -> 100.76923 | H15: ='All Seasons'!M36 -> 7 | I15: ='All Seasons'!N36 -> 5 | J15: =IF('All Seasons'!O36=1,"YES","-") -> YES
A16: ='All Seasons'!B37 -> 12 | B16: ='All Seasons'!C37 -> Scott's Scabs | C16: ='All Seasons'!D37 -> Scott | D16: ='All Seasons'!I37 -> 2-11-0 | E16: ='All Seasons'!J37 -> 0.15384615 | F16: ='All Seasons'!K37 -> 1307 | G16: ='All Seasons'!L37 -> 100.53846 | H16: ='All Seasons'!M37 -> 8 | I16: ='All Seasons'!N37 -> 12 | J16: =IF('All Seasons'!O37=1,"YES","-") -> -
B17: League total / average | E17: =AVERAGE(E5:E16) -> 0.5 | F17: =SUM(F5:F16) -> 16440 | G17: =AVERAGE(G5:G16) -> 105.38462
A19: Correlation with draft slot (this season)
A20: Win % | C20: =CORREL($A$5:$A$16,E5:E16) -> -0.29627334
A21: Pts/Game | C21: =CORREL($A$5:$A$16,G5:G16) -> 0.090537685
A22: PF Rank (1=most pts) | C22: =CORREL($A$5:$A$16,H5:H16) -> -0.15384615
A23: Final Finish (1=champ) | C23: =CORREL($A$5:$A$16,I5:I16) -> 0.16783217
A24: Negative on Win % / Pts-Game = earlier picks did better. Positive on PF Rank / Final Finish = earlier picks did better.

Sheet Season 2014
A1: 2014 season — ordered by draft slot
A2: 13-game regular season · 12 teams · 6 playoff spots · pick 1 = first overall
A4: Draft Slot | B4: Team | C4: Manager | D4: Record | E4: Win % | F4: Points For | G4: Pts/Game | H4: PF Rank | I4: Final Finish | J4: Made Playoffs?
A5: ='All Seasons'!B38 -> 1 | B5: ='All Seasons'!C38 -> RedZone480 | C5: ='All Seasons'!D38 -> Robert | D5: ='All Seasons'!I38 -> 6-7-0 | E5: ='All Seasons'!J38 -> 0.46153846 | F5: ='All Seasons'!K38 -> 1255 | G5: ='All Seasons'!L38 -> 96.538462 | H5: ='All Seasons'!M38 -> 9 | I5: ='All Seasons'!N38 -> 9 | J5: =IF('All Seasons'!O38=1,"YES","-") -> -
A6: ='All Seasons'!B39 -> 2 | B6: ='All Seasons'!C39 -> Spike's Chupacabras | C6: ='All Seasons'!D39 -> Spike | D6: ='All Seasons'!I39 -> 6-7-0 | E6: ='All Seasons'!J39 -> 0.46153846 | F6: ='All Seasons'!K39 -> 1258 | G6: ='All Seasons'!L39 -> 96.769231 | H6: ='All Seasons'!M39 -> 8 | I6: ='All Seasons'!N39 -> 7 | J6: =IF('All Seasons'!O39=1,"YES","-") -> -
A7: ='All Seasons'!B40 -> 3 | B7: ='All Seasons'!C40 -> Closer | C7: ='All Seasons'!D40 -> Rick | D7: ='All Seasons'!I40 -> 9-4-0 | E7: ='All Seasons'!J40 -> 0.69230769 | F7: ='All Seasons'!K40 -> 1545 | G7: ='All Seasons'!L40 -> 118.84615 | H7: ='All Seasons'!M40 -> 2 | I7: ='All Seasons'!N40 -> 4 | J7: =IF('All Seasons'!O40=1,"YES","-") -> YES
A8: ='All Seasons'!B41 -> 4 | B8: ='All Seasons'!C41 -> RedNecks | C8: ='All Seasons'!D41 -> Jim | D8: ='All Seasons'!I41 -> 4-9-0 | E8: ='All Seasons'!J41 -> 0.30769231 | F8: ='All Seasons'!K41 -> 1199 | G8: ='All Seasons'!L41 -> 92.230769 | H8: ='All Seasons'!M41 -> 11 | I8: ='All Seasons'!N41 -> 11 | J8: =IF('All Seasons'!O41=1,"YES","-") -> -
A9: ='All Seasons'!B42 -> 5 | B9: ='All Seasons'!C42 -> Scott's Scabs | C9: ='All Seasons'!D42 -> Scott | D9: ='All Seasons'!I42 -> 9-4-0 | E9: ='All Seasons'!J42 -> 0.69230769 | F9: ='All Seasons'!K42 -> 1372 | G9: ='All Seasons'!L42 -> 105.53846 | H9: ='All Seasons'!M42 -> 5 | I9: ='All Seasons'!N42 -> 6 | J9: =IF('All Seasons'!O42=1,"YES","-") -> YES
A10: ='All Seasons'!B43 -> 6 | B10: ='All Seasons'!C43 -> Crackerman | C10: ='All Seasons'!D43 -> Michael M | D10: ='All Seasons'!I43 -> 4-9-0 | E10: ='All Seasons'!J43 -> 0.30769231 | F10: ='All Seasons'!K43 -> 1253 | G10: ='All Seasons'!L43 -> 96.384615 | H10: ='All Seasons'!M43 -> 10 | I10: ='All Seasons'!N43 -> 12 | J10: =IF('All Seasons'!O43=1,"YES","-") -> -
A11: ='All Seasons'!B44 -> 7 | B11: ='All Seasons'!C44 -> Donkey Punchers | C11: ='All Seasons'!D44 -> Barrett | D11: ='All Seasons'!I44 -> 3-10-0 | E11: ='All Seasons'!J44 -> 0.23076923 | F11: ='All Seasons'!K44 -> 1326 | G11: ='All Seasons'!L44 -> 102 | H11: ='All Seasons'!M44 -> 7 | I11: ='All Seasons'!N44 -> 8 | J11: =IF('All Seasons'!O44=1,"YES","-") -> -
A12: ='All Seasons'!B45 -> 8 | B12: ='All Seasons'!C45 -> Big Red Machine | C12: ='All Seasons'!D45 -> Cory | D12: ='All Seasons'!I45 -> 10-3-0 | E12: ='All Seasons'!J45 -> 0.76923077 | F12: ='All Seasons'!K45 -> 1620 | G12: ='All Seasons'!L45 -> 124.61538 | H12: ='All Seasons'!M45 -> 1 | I12: ='All Seasons'!N45 -> 1 | J12: =IF('All Seasons'!O45=1,"YES","-") -> YES
A13: ='All Seasons'!B46 -> 9 | B13: ='All Seasons'!C46 -> Going Postal | C13: ='All Seasons'!D46 -> Steve | D13: ='All Seasons'!I46 -> 7-6-0 | E13: ='All Seasons'!J46 -> 0.53846154 | F13: ='All Seasons'!K46 -> 1351 | G13: ='All Seasons'!L46 -> 103.92308 | H13: ='All Seasons'!M46 -> 6 | I13: ='All Seasons'!N46 -> 5 | J13: =IF('All Seasons'!O46=1,"YES","-") -> YES
A14: ='All Seasons'!B47 -> 10 | B14: ='All Seasons'!C47 -> Golden Taint | C14: ='All Seasons'!D47 -> Keith | D14: ='All Seasons'!I47 -> 10-3-0 | E14: ='All Seasons'!J47 -> 0.76923077 | F14: ='All Seasons'!K47 -> 1530 | G14: ='All Seasons'!L47 -> 117.69231 | H14: ='All Seasons'!M47 -> 3 | I14: ='All Seasons'!N47 -> 2 | J14: =IF('All Seasons'!O47=1,"YES","-") -> YES
A15: ='All Seasons'!B48 -> 11 | B15: ='All Seasons'!C48 -> AssKickers | C15: ='All Seasons'!D48 -> Rob M | D15: ='All Seasons'!I48 -> 7-6-0 | E15: ='All Seasons'!J48 -> 0.53846154 | F15: ='All Seasons'!K48 -> 1384 | G15: ='All Seasons'!L48 -> 106.46154 | H15: ='All Seasons'!M48 -> 4 | I15: ='All Seasons'!N48 -> 3 | J15: =IF('All Seasons'!O48=1,"YES","-") -> YES
A16: ='All Seasons'!B49 -> 12 | B16: ='All Seasons'!C49 -> Vandalay Industries | C16: ='All Seasons'!D49 -> John | D16: ='All Seasons'!I49 -> 3-10-0 | E16: ='All Seasons'!J49 -> 0.23076923 | F16: ='All Seasons'!K49 -> 1120 | G16: ='All Seasons'!L49 -> 86.153846 | H16: ='All Seasons'!M49 -> 12 | I16: ='All Seasons'!N49 -> 10 | J16: =IF('All Seasons'!O49=1,"YES","-") -> -
B17: League total / average | E17: =AVERAGE(E5:E16) -> 0.5 | F17: =SUM(F5:F16) -> 16213 | G17: =AVERAGE(G5:G16) -> 103.92949
A19: Correlation with draft slot (this season)
A20: Win % | C20: =CORREL($A$5:$A$16,E5:E16) -> 0
A21: Pts/Game | C21: =CORREL($A$5:$A$16,G5:G16) -> 0.094095891
A22: PF Rank (1=most pts) | C22: =CORREL($A$5:$A$16,H5:H16) -> -0.12587413
A23: Final Finish (1=champ) | C23: =CORREL($A$5:$A$16,I5:I16) -> -0.30769231
A24: Negative on Win % / Pts-Game = earlier picks did better. Positive on PF Rank / Final Finish = earlier picks did better.

Sheet Season 2015
A1: 2015 season — ordered by draft slot
A2: 13-game regular season · 12 teams · 6 playoff spots · pick 1 = first overall
A4: Draft Slot | B4: Team | C4: Manager | D4: Record | E4: Win % | F4: Points For | G4: Pts/Game | H4: PF Rank | I4: Final Finish | J4: Made Playoffs?
A5: ='All Seasons'!B50 -> 1 | B5: ='All Seasons'!C50 -> Vandalay Industries | C5: ='All Seasons'!D50 -> John | D5: ='All Seasons'!I50 -> 10-3-0 | E5: ='All Seasons'!J50 -> 0.76923077 | F5: ='All Seasons'!K50 -> 1472 | G5: ='All Seasons'!L50 -> 113.23077 | H5: ='All Seasons'!M50 -> 2 | I5: ='All Seasons'!N50 -> 2 | J5: =IF('All Seasons'!O50=1,"YES","-") -> YES
A6: ='All Seasons'!B51 -> 2 | B6: ='All Seasons'!C51 -> Golden Taint | C6: ='All Seasons'!D51 -> Keith | D6: ='All Seasons'!I51 -> 8-5-0 | E6: ='All Seasons'!J51 -> 0.61538462 | F6: ='All Seasons'!K51 -> 1587 | G6: ='All Seasons'!L51 -> 122.07692 | H6: ='All Seasons'!M51 -> 1 | I6: ='All Seasons'!N51 -> 5 | J6: =IF('All Seasons'!O51=1,"YES","-") -> YES
A7: ='All Seasons'!B52 -> 3 | B7: ='All Seasons'!C52 -> RedNecks | C7: ='All Seasons'!D52 -> Jim | D7: ='All Seasons'!I52 -> 5-8-0 | E7: ='All Seasons'!J52 -> 0.38461538 | F7: ='All Seasons'!K52 -> 1325 | G7: ='All Seasons'!L52 -> 101.92308 | H7: ='All Seasons'!M52 -> 7 | I7: ='All Seasons'!N52 -> 11 | J7: =IF('All Seasons'!O52=1,"YES","-") -> -
A8: ='All Seasons'!B53 -> 4 | B8: ='All Seasons'!C53 -> RedZone480 | C8: ='All Seasons'!D53 -> Robert | D8: ='All Seasons'!I53 -> 5-8-0 | E8: ='All Seasons'!J53 -> 0.38461538 | F8: ='All Seasons'!K53 -> 1271 | G8: ='All Seasons'!L53 -> 97.769231 | H8: ='All Seasons'!M53 -> 9 | I8: ='All Seasons'!N53 -> 4 | J8: =IF('All Seasons'!O53=1,"YES","-") -> YES
A9: ='All Seasons'!B54 -> 5 | B9: ='All Seasons'!C54 -> AssKickers | C9: ='All Seasons'!D54 -> Rob M | D9: ='All Seasons'!I54 -> 5-8-0 | E9: ='All Seasons'!J54 -> 0.38461538 | F9: ='All Seasons'!K54 -> 1192 | G9: ='All Seasons'!L54 -> 91.692308 | H9: ='All Seasons'!M54 -> 11 | I9: ='All Seasons'!N54 -> 12 | J9: =IF('All Seasons'!O54=1,"YES","-") -> -
A10: ='All Seasons'!B55 -> 6 | B10: ='All Seasons'!C55 -> Scott's Scabs | C10: ='All Seasons'!D55 -> Scott | D10: ='All Seasons'!I55 -> 5-8-0 | E10: ='All Seasons'!J55 -> 0.38461538 | F10: ='All Seasons'!K55 -> 1391 | G10: ='All Seasons'!L55 -> 107 | H10: ='All Seasons'!M55 -> 3 | I10: ='All Seasons'!N55 -> 10 | J10: =IF('All Seasons'!O55=1,"YES","-") -> -
A11: ='All Seasons'!B56 -> 7 | B11: ='All Seasons'!C56 -> Big Red Machine | C11: ='All Seasons'!D56 -> Cory | D11: ='All Seasons'!I56 -> 8-5-0 | E11: ='All Seasons'!J56 -> 0.61538462 | F11: ='All Seasons'!K56 -> 1345 | G11: ='All Seasons'!L56 -> 103.46154 | H11: ='All Seasons'!M56 -> 6 | I11: ='All Seasons'!N56 -> 6 | J11: =IF('All Seasons'!O56=1,"YES","-") -> YES
A12: ='All Seasons'!B57 -> 8 | B12: ='All Seasons'!C57 -> Closer | C12: ='All Seasons'!D57 -> Rick | D12: ='All Seasons'!I57 -> 6-7-0 | E12: ='All Seasons'!J57 -> 0.46153846 | F12: ='All Seasons'!K57 -> 1271 | G12: ='All Seasons'!L57 -> 97.769231 | H12: ='All Seasons'!M57 -> 9 | I12: ='All Seasons'!N57 -> 8 | J12: =IF('All Seasons'!O57=1,"YES","-") -> -
A13: ='All Seasons'!B58 -> 9 | B13: ='All Seasons'!C58 -> Going Postal | C13: ='All Seasons'!D58 -> Steve | D13: ='All Seasons'!I58 -> 7-6-0 | E13: ='All Seasons'!J58 -> 0.53846154 | F13: ='All Seasons'!K58 -> 1382 | G13: ='All Seasons'!L58 -> 106.30769 | H13: ='All Seasons'!M58 -> 4 | I13: ='All Seasons'!N58 -> 3 | J13: =IF('All Seasons'!O58=1,"YES","-") -> YES
A14: ='All Seasons'!B59 -> 10 | B14: ='All Seasons'!C59 -> Crackerman | C14: ='All Seasons'!D59 -> Michael M | D14: ='All Seasons'!I59 -> 8-5-0 | E14: ='All Seasons'!J59 -> 0.61538462 | F14: ='All Seasons'!K59 -> 1378 | G14: ='All Seasons'!L59 -> 106 | H14: ='All Seasons'!M59 -> 5 | I14: ='All Seasons'!N59 -> 1 | J14: =IF('All Seasons'!O59=1,"YES","-") -> YES
A15: ='All Seasons'!B60 -> 11 | B15: ='All Seasons'!C60 -> Donkey Punchers | C15: ='All Seasons'!D60 -> Barrett | D15: ='All Seasons'!I60 -> 5-8-0 | E15: ='All Seasons'!J60 -> 0.38461538 | F15: ='All Seasons'!K60 -> 1294 | G15: ='All Seasons'!L60 -> 99.538462 | H15: ='All Seasons'!M60 -> 8 | I15: ='All Seasons'!N60 -> 9 | J15: =IF('All Seasons'!O60=1,"YES","-") -> -
A16: ='All Seasons'!B61 -> 12 | B16: ='All Seasons'!C61 -> Spike's Chupacabras | C16: ='All Seasons'!D61 -> Spike | D16: ='All Seasons'!I61 -> 6-7-0 | E16: ='All Seasons'!J61 -> 0.46153846 | F16: ='All Seasons'!K61 -> 1185 | G16: ='All Seasons'!L61 -> 91.153846 | H16: ='All Seasons'!M61 -> 12 | I16: ='All Seasons'!N61 -> 7 | J16: =IF('All Seasons'!O61=1,"YES","-") -> -
B17: League total / average | E17: =AVERAGE(E5:E16) -> 0.5 | F17: =SUM(F5:F16) -> 16093 | G17: =AVERAGE(G5:G16) -> 103.16026
A19: Correlation with draft slot (this season)
A20: Win % | C20: =CORREL($A$5:$A$16,E5:E16) -> -0.25532895
A21: Pts/Game | C21: =CORREL($A$5:$A$16,G5:G16) -> -0.51886755
A22: PF Rank (1=most pts) | C22: =CORREL($A$5:$A$16,H5:H16) -> 0.46810699
A23: Final Finish (1=champ) | C23: =CORREL($A$5:$A$16,I5:I16) -> 0
A24: Negative on Win % / Pts-Game = earlier picks did better. Positive on PF Rank / Final Finish = earlier picks did better.

Sheet Season 2016
A1: 2016 season — ordered by draft slot
A2: 13-game regular season · 12 teams · 6 playoff spots · pick 1 = first overall
A4: Draft Slot | B4: Team | C4: Manager | D4: Record | E4: Win % | F4: Points For | G4: Pts/Game | H4: PF Rank | I4: Final Finish | J4: Made Playoffs?
A5: ='All Seasons'!B62 -> 1 | B5: ='All Seasons'!C62 -> Donkey Punchers | C5: ='All Seasons'!D62 -> Barrett | D5: ='All Seasons'!I62 -> 10-3-0 | E5: ='All Seasons'!J62 -> 0.76923077 | F5: ='All Seasons'!K62 -> 1474 | G5: ='All Seasons'!L62 -> 113.38462 | H5: ='All Seasons'!M62 -> 1 | I5: ='All Seasons'!N62 -> 1 | J5: =IF('All Seasons'!O62=1,"YES","-") -> YES
A6: ='All Seasons'!B63 -> 2 | B6: ='All Seasons'!C63 -> Boda's Buttkickers | C6: ='All Seasons'!D63 -> Greg | D6: ='All Seasons'!I63 -> 6-7-0 | E6: ='All Seasons'!J63 -> 0.46153846 | F6: ='All Seasons'!K63 -> 1307 | G6: ='All Seasons'!L63 -> 100.53846 | H6: ='All Seasons'!M63 -> 7 | I6: ='All Seasons'!N63 -> 7 | J6: =IF('All Seasons'!O63=1,"YES","-") -> -
A7: ='All Seasons'!B64 -> 3 | B7: ='All Seasons'!C64 -> AssKickers | C7: ='All Seasons'!D64 -> Rob M | D7: ='All Seasons'!I64 -> 8-5-0 | E7: ='All Seasons'!J64 -> 0.61538462 | F7: ='All Seasons'!K64 -> 1458 | G7: ='All Seasons'!L64 -> 112.15385 | H7: ='All Seasons'!M64 -> 2 | I7: ='All Seasons'!N64 -> 2 | J7: =IF('All Seasons'!O64=1,"YES","-") -> YES
A8: ='All Seasons'!B65 -> 4 | B8: ='All Seasons'!C65 -> RedNecks | C8: ='All Seasons'!D65 -> Jim | D8: ='All Seasons'!I65 -> 9-4-0 | E8: ='All Seasons'!J65 -> 0.69230769 | F8: ='All Seasons'!K65 -> 1441 | G8: ='All Seasons'!L65 -> 110.84615 | H8: ='All Seasons'!M65 -> 4 | I8: ='All Seasons'!N65 -> 4 | J8: =IF('All Seasons'!O65=1,"YES","-") -> YES
A9: ='All Seasons'!B66 -> 5 | B9: ='All Seasons'!C66 -> Ziggy Starfish | C9: ='All Seasons'!D66 -> Keith | D9: ='All Seasons'!I66 -> 8-5-0 | E9: ='All Seasons'!J66 -> 0.61538462 | F9: ='All Seasons'!K66 -> 1457 | G9: ='All Seasons'!L66 -> 112.07692 | H9: ='All Seasons'!M66 -> 3 | I9: ='All Seasons'!N66 -> 3 | J9: =IF('All Seasons'!O66=1,"YES","-") -> YES
A10: ='All Seasons'!B67 -> 6 | B10: ='All Seasons'!C67 -> Scott's Scabs | C10: ='All Seasons'!D67 -> Scott | D10: ='All Seasons'!I67 -> 4-9-0 | E10: ='All Seasons'!J67 -> 0.30769231 | F10: ='All Seasons'!K67 -> 1387 | G10: ='All Seasons'!L67 -> 106.69231 | H10: ='All Seasons'!M67 -> 5 | I10: ='All Seasons'!N67 -> 8 | J10: =IF('All Seasons'!O67=1,"YES","-") -> -
A11: ='All Seasons'!B68 -> 7 | B11: ='All Seasons'!C68 -> Vandalay Industries | C11: ='All Seasons'!D68 -> John | D11: ='All Seasons'!I68 -> 4-9-0 | E11: ='All Seasons'!J68 -> 0.30769231 | F11: ='All Seasons'!K68 -> 1221 | G11: ='All Seasons'!L68 -> 93.923077 | H11: ='All Seasons'!M68 -> 11 | I11: ='All Seasons'!N68 -> 12 | J11: =IF('All Seasons'!O68=1,"YES","-") -> -
A12: ='All Seasons'!B69 -> 8 | B12: ='All Seasons'!C69 -> Closer | C12: ='All Seasons'!D69 -> Rick | D12: ='All Seasons'!I69 -> 6-7-0 | E12: ='All Seasons'!J69 -> 0.46153846 | F12: ='All Seasons'!K69 -> 1262 | G12: ='All Seasons'!L69 -> 97.076923 | H12: ='All Seasons'!M69 -> 9 | I12: ='All Seasons'!N69 -> 6 | J12: =IF('All Seasons'!O69=1,"YES","-") -> YES
A13: ='All Seasons'!B70 -> 9 | B13: ='All Seasons'!C70 -> Big Red Machine | C13: ='All Seasons'!D70 -> Cory | D13: ='All Seasons'!I70 -> 4-9-0 | E13: ='All Seasons'!J70 -> 0.30769231 | F13: ='All Seasons'!K70 -> 1282 | G13: ='All Seasons'!L70 -> 98.615385 | H13: ='All Seasons'!M70 -> 8 | I13: ='All Seasons'!N70 -> 10 | J13: =IF('All Seasons'!O70=1,"YES","-") -> -
A14: ='All Seasons'!B71 -> 10 | B14: ='All Seasons'!C71 -> Spike's Chupacabras | C14: ='All Seasons'!D71 -> Spike | D14: ='All Seasons'!I71 -> 6-7-0 | E14: ='All Seasons'!J71 -> 0.46153846 | F14: ='All Seasons'!K71 -> 1247 | G14: ='All Seasons'!L71 -> 95.923077 | H14: ='All Seasons'!M71 -> 10 | I14: ='All Seasons'!N71 -> 9 | J14: =IF('All Seasons'!O71=1,"YES","-") -> -
A15: ='All Seasons'!B72 -> 11 | B15: ='All Seasons'!C72 -> RedZone480 | C15: ='All Seasons'!D72 -> Robert | D15: ='All Seasons'!I72 -> 9-4-0 | E15: ='All Seasons'!J72 -> 0.69230769 | F15: ='All Seasons'!K72 -> 1378 | G15: ='All Seasons'!L72 -> 106 | H15: ='All Seasons'!M72 -> 6 | I15: ='All Seasons'!N72 -> 5 | J15: =IF('All Seasons'!O72=1,"YES","-") -> YES
A16: ='All Seasons'!B73 -> 12 | B16: ='All Seasons'!C73 -> Going Postal | C16: ='All Seasons'!D73 -> Steve | D16: ='All Seasons'!I73 -> 4-9-0 | E16: ='All Seasons'!J73 -> 0.30769231 | F16: ='All Seasons'!K73 -> 1159 | G16: ='All Seasons'!L73 -> 89.153846 | H16: ='All Seasons'!M73 -> 12 | I16: ='All Seasons'!N73 -> 11 | J16: =IF('All Seasons'!O73=1,"YES","-") -> -
B17: League total / average | E17: =AVERAGE(E5:E16) -> 0.5 | F17: =SUM(F5:F16) -> 16073 | G17: =AVERAGE(G5:G16) -> 103.03205
A19: Correlation with draft slot (this season)
A20: Win % | C20: =CORREL($A$5:$A$16,E5:E16) -> -0.47358717
A21: Pts/Game | C21: =CORREL($A$5:$A$16,G5:G16) -> -0.69026392
A22: PF Rank (1=most pts) | C22: =CORREL($A$5:$A$16,H5:H16) -> 0.74125874
A23: Final Finish (1=champ) | C23: =CORREL($A$5:$A$16,I5:I16) -> 0.64335664
A24: Negative on Win % / Pts-Game = earlier picks did better. Positive on PF Rank / Final Finish = earlier picks did better.

Sheet Season 2017
A1: 2017 season — ordered by draft slot
A2: 13-game regular season · 12 teams · 6 playoff spots · pick 1 = first overall
A4: Draft Slot | B4: Team | C4: Manager | D4: Record | E4: Win % | F4: Points For | G4: Pts/Game | H4: PF Rank | I4: Final Finish | J4: Made Playoffs?
A5: ='All Seasons'!B74 -> 1 | B5: ='All Seasons'!C74 -> Donkey Punchers | C5: ='All Seasons'!D74 -> Barrett | D5: ='All Seasons'!I74 -> 10-3-0 | E5: ='All Seasons'!J74 -> 0.76923077 | F5: ='All Seasons'!K74 -> 1402 | G5: ='All Seasons'!L74 -> 107.84615 | H5: ='All Seasons'!M74 -> 2 | I5: ='All Seasons'!N74 -> 4 | J5: =IF('All Seasons'!O74=1,"YES","-") -> YES
A6: ='All Seasons'!B75 -> 2 | B6: ='All Seasons'!C75 -> AssKickers | C6: ='All Seasons'!D75 -> Rob M | D6: ='All Seasons'!I75 -> 4-9-0 | E6: ='All Seasons'!J75 -> 0.30769231 | F6: ='All Seasons'!K75 -> 1331 | G6: ='All Seasons'!L75 -> 102.38462 | H6: ='All Seasons'!M75 -> 3 | I6: ='All Seasons'!N75 -> 10 | J6: =IF('All Seasons'!O75=1,"YES","-") -> -
A7: ='All Seasons'!B76 -> 3 | B7: ='All Seasons'!C76 -> Ziggy Starfish | C7: ='All Seasons'!D76 -> Keith | D7: ='All Seasons'!I76 -> 12-1-0 | E7: ='All Seasons'!J76 -> 0.92307692 | F7: ='All Seasons'!K76 -> 1618 | G7: ='All Seasons'!L76 -> 124.46154 | H7: ='All Seasons'!M76 -> 1 | I7: ='All Seasons'!N76 -> 2 | J7: =IF('All Seasons'!O76=1,"YES","-") -> YES
A8: ='All Seasons'!B77 -> 4 | B8: ='All Seasons'!C77 -> Vandalay Industries | C8: ='All Seasons'!D77 -> John | D8: ='All Seasons'!I77 -> 6-7-0 | E8: ='All Seasons'!J77 -> 0.46153846 | F8: ='All Seasons'!K77 -> 1167 | G8: ='All Seasons'!L77 -> 89.769231 | H8: ='All Seasons'!M77 -> 9 | I8: ='All Seasons'!N77 -> 7 | J8: =IF('All Seasons'!O77=1,"YES","-") -> -
A9: ='All Seasons'!B78 -> 5 | B9: ='All Seasons'!C78 -> Closer | C9: ='All Seasons'!D78 -> Rick | D9: ='All Seasons'!I78 -> 7-6-0 | E9: ='All Seasons'!J78 -> 0.53846154 | F9: ='All Seasons'!K78 -> 1286 | G9: ='All Seasons'!L78 -> 98.923077 | H9: ='All Seasons'!M78 -> 6 | I9: ='All Seasons'!N78 -> 1 | J9: =IF('All Seasons'!O78=1,"YES","-") -> YES
A10: ='All Seasons'!B79 -> 6 | B10: ='All Seasons'!C79 -> Spike's Chupacabras | C10: ='All Seasons'!D79 -> Spike | D10: ='All Seasons'!I79 -> 3-10-0 | E10: ='All Seasons'!J79 -> 0.23076923 | F10: ='All Seasons'!K79 -> 1067 | G10: ='All Seasons'!L79 -> 82.076923 | H10: ='All Seasons'!M79 -> 12 | I10: ='All Seasons'!N79 -> 9 | J10: =IF('All Seasons'!O79=1,"YES","-") -> -
A11: ='All Seasons'!B80 -> 7 | B11: ='All Seasons'!C80 -> Scott's Scabs | C11: ='All Seasons'!D80 -> Scott | D11: ='All Seasons'!I80 -> 6-7-0 | E11: ='All Seasons'!J80 -> 0.46153846 | F11: ='All Seasons'!K80 -> 1221 | G11: ='All Seasons'!L80 -> 93.923077 | H11: ='All Seasons'!M80 -> 8 | I11: ='All Seasons'!N80 -> 8 | J11: =IF('All Seasons'!O80=1,"YES","-") -> -
A12: ='All Seasons'!B81 -> 8 | B12: ='All Seasons'!C81 -> Boda's Buttkickers | C12: ='All Seasons'!D81 -> Greg | D12: ='All Seasons'!I81 -> 3-10-0 | E12: ='All Seasons'!J81 -> 0.23076923 | F12: ='All Seasons'!K81 -> 1086 | G12: ='All Seasons'!L81 -> 83.538462 | H12: ='All Seasons'!M81 -> 11 | I12: ='All Seasons'!N81 -> 12 | J12: =IF('All Seasons'!O81=1,"YES","-") -> -
A13: ='All Seasons'!B82 -> 9 | B13: ='All Seasons'!C82 -> Going Postal | C13: ='All Seasons'!D82 -> Steve | D13: ='All Seasons'!I82 -> 6-7-0 | E13: ='All Seasons'!J82 -> 0.46153846 | F13: ='All Seasons'!K82 -> 1224 | G13: ='All Seasons'!L82 -> 94.153846 | H13: ='All Seasons'!M82 -> 7 | I13: ='All Seasons'!N82 -> 6 | J13: =IF('All Seasons'!O82=1,"YES","-") -> YES
A14: ='All Seasons'!B83 -> 10 | B14: ='All Seasons'!C83 -> RedNecks | C14: ='All Seasons'!D83 -> Jim | D14: ='All Seasons'!I83 -> 5-8-0 | E14: ='All Seasons'!J83 -> 0.38461538 | F14: ='All Seasons'!K83 -> 1157 | G14: ='All Seasons'!L83 -> 89 | H14: ='All Seasons'!M83 -> 10 | I14: ='All Seasons'!N83 -> 11 | J14: =IF('All Seasons'!O83=1,"YES","-") -> -
A15: ='All Seasons'!B84 -> 11 | B15: ='All Seasons'!C84 -> Big Red Machine | C15: ='All Seasons'!D84 -> Cory | D15: ='All Seasons'!I84 -> 8-5-0 | E15: ='All Seasons'!J84 -> 0.61538462 | F15: ='All Seasons'!K84 -> 1323 | G15: ='All Seasons'!L84 -> 101.76923 | H15: ='All Seasons'!M84 -> 4 | I15: ='All Seasons'!N84 -> 5 | J15: =IF('All Seasons'!O84=1,"YES","-") -> YES
A16: ='All Seasons'!B85 -> 12 | B16: ='All Seasons'!C85 -> RedZone480 | C16: ='All Seasons'!D85 -> Robert | D16: ='All Seasons'!I85 -> 8-5-0 | E16: ='All Seasons'!J85 -> 0.61538462 | F16: ='All Seasons'!K85 -> 1306 | G16: ='All Seasons'!L85 -> 100.46154 | H16: ='All Seasons'!M85 -> 5 | I16: ='All Seasons'!N85 -> 3 | J16: =IF('All Seasons'!O85=1,"YES","-") -> YES
B17: League total / average | E17: =AVERAGE(E5:E16) -> 0.5 | F17: =SUM(F5:F16) -> 15188 | G17: =AVERAGE(G5:G16) -> 97.358974
A19: Correlation with draft slot (this season)
A20: Win % | C20: =CORREL($A$5:$A$16,E5:E16) -> -0.20441471
A21: Pts/Game | C21: =CORREL($A$5:$A$16,G5:G16) -> -0.37814284
A22: PF Rank (1=most pts) | C22: =CORREL($A$5:$A$16,H5:H16) -> 0.37062937
A23: Final Finish (1=champ) | C23: =CORREL($A$5:$A$16,I5:I16) -> 0.11888112
A24: Negative on Win % / Pts-Game = earlier picks did better. Positive on PF Rank / Final Finish = earlier picks did better.

Sheet Season 2018
A1: 2018 season — ordered by draft slot
A2: 13-game regular season · 12 teams · 6 playoff spots · pick 1 = first overall
A4: Draft Slot | B4: Team | C4: Manager | D4: Record | E4: Win % | F4: Points For | G4: Pts/Game | H4: PF Rank | I4: Final Finish | J4: Made Playoffs?
A5: ='All Seasons'!B86 -> 1 | B5: ='All Seasons'!C86 -> RedZone480 | C5: ='All Seasons'!D86 -> Robert | D5: ='All Seasons'!I86 -> 7-6-0 | E5: ='All Seasons'!J86 -> 0.53846154 | F5: ='All Seasons'!K86 -> 1570 | G5: ='All Seasons'!L86 -> 120.76923 | H5: ='All Seasons'!M86 -> 2 | I5: ='All Seasons'!N86 -> 2 | J5: =IF('All Seasons'!O86=1,"YES","-") -> YES
A6: ='All Seasons'!B87 -> 2 | B6: ='All Seasons'!C87 -> Scott's Scabs | C6: ='All Seasons'!D87 -> Scott | D6: ='All Seasons'!I87 -> 3-10-0 | E6: ='All Seasons'!J87 -> 0.23076923 | F6: ='All Seasons'!K87 -> 1294 | G6: ='All Seasons'!L87 -> 99.538462 | H6: ='All Seasons'!M87 -> 10 | I6: ='All Seasons'!N87 -> 8 | J6: =IF('All Seasons'!O87=1,"YES","-") -> -
A7: ='All Seasons'!B88 -> 3 | B7: ='All Seasons'!C88 -> Going Postal | C7: ='All Seasons'!D88 -> Steve | D7: ='All Seasons'!I88 -> 9-4-0 | E7: ='All Seasons'!J88 -> 0.69230769 | F7: ='All Seasons'!K88 -> 1565 | G7: ='All Seasons'!L88 -> 120.38462 | H7: ='All Seasons'!M88 -> 3 | I7: ='All Seasons'!N88 -> 6 | J7: =IF('All Seasons'!O88=1,"YES","-") -> YES
A8: ='All Seasons'!B89 -> 4 | B8: ='All Seasons'!C89 -> #YouToo | C8: ='All Seasons'!D89 -> Keith | D8: ='All Seasons'!I89 -> 8-5-0 | E8: ='All Seasons'!J89 -> 0.61538462 | F8: ='All Seasons'!K89 -> 1651 | G8: ='All Seasons'!L89 -> 127 | H8: ='All Seasons'!M89 -> 1 | I8: ='All Seasons'!N89 -> 5 | J8: =IF('All Seasons'!O89=1,"YES","-") -> YES
A9: ='All Seasons'!B90 -> 5 | B9: ='All Seasons'!C90 -> RedNecks | C9: ='All Seasons'!D90 -> Jim | D9: ='All Seasons'!I90 -> 3-10-0 | E9: ='All Seasons'!J90 -> 0.23076923 | F9: ='All Seasons'!K90 -> 1142 | G9: ='All Seasons'!L90 -> 87.846154 | H9: ='All Seasons'!M90 -> 12 | I9: ='All Seasons'!N90 -> 11 | J9: =IF('All Seasons'!O90=1,"YES","-") -> -
A10: ='All Seasons'!B91 -> 6 | B10: ='All Seasons'!C91 -> Spike's Chupacabras | C10: ='All Seasons'!D91 -> Spike | D10: ='All Seasons'!I91 -> 5-8-0 | E10: ='All Seasons'!J91 -> 0.38461538 | F10: ='All Seasons'!K91 -> 1331 | G10: ='All Seasons'!L91 -> 102.38462 | H10: ='All Seasons'!M91 -> 9 | I10: ='All Seasons'!N91 -> 7 | J10: =IF('All Seasons'!O91=1,"YES","-") -> -
A11: ='All Seasons'!B92 -> 7 | B11: ='All Seasons'!C92 -> Eagles got a big Cox | C11: ='All Seasons'!D92 -> Brian C | D11: ='All Seasons'!I92 -> 4-9-0 | E11: ='All Seasons'!J92 -> 0.30769231 | F11: ='All Seasons'!K92 -> 1380 | G11: ='All Seasons'!L92 -> 106.15385 | H11: ='All Seasons'!M92 -> 7 | I11: ='All Seasons'!N92 -> 9 | J11: =IF('All Seasons'!O92=1,"YES","-") -> -
A12: ='All Seasons'!B93 -> 8 | B12: ='All Seasons'!C93 -> Closer | C12: ='All Seasons'!D93 -> Rick | D12: ='All Seasons'!I93 -> 10-3-0 | E12: ='All Seasons'!J93 -> 0.76923077 | F12: ='All Seasons'!K93 -> 1500 | G12: ='All Seasons'!L93 -> 115.38462 | H12: ='All Seasons'!M93 -> 5 | I12: ='All Seasons'!N93 -> 1 | J12: =IF('All Seasons'!O93=1,"YES","-") -> YES
A13: ='All Seasons'!B94 -> 9 | B13: ='All Seasons'!C94 -> Mean Machine | C13: ='All Seasons'!D94 -> Cory | D13: ='All Seasons'!I94 -> 9-4-0 | E13: ='All Seasons'!J94 -> 0.69230769 | F13: ='All Seasons'!K94 -> 1389 | G13: ='All Seasons'!L94 -> 106.84615 | H13: ='All Seasons'!M94 -> 6 | I13: ='All Seasons'!N94 -> 4 | J13: =IF('All Seasons'!O94=1,"YES","-") -> YES
A14: ='All Seasons'!B95 -> 10 | B14: ='All Seasons'!C95 -> Donkey Punchers | C14: ='All Seasons'!D95 -> Barrett | D14: ='All Seasons'!I95 -> 4-9-0 | E14: ='All Seasons'!J95 -> 0.30769231 | F14: ='All Seasons'!K95 -> 1202 | G14: ='All Seasons'!L95 -> 92.461538 | H14: ='All Seasons'!M95 -> 11 | I14: ='All Seasons'!N95 -> 12 | J14: =IF('All Seasons'!O95=1,"YES","-") -> -
A15: ='All Seasons'!B96 -> 11 | B15: ='All Seasons'!C96 -> AssKickers | C15: ='All Seasons'!D96 -> Rob M | D15: ='All Seasons'!I96 -> 6-7-0 | E15: ='All Seasons'!J96 -> 0.46153846 | F15: ='All Seasons'!K96 -> 1376 | G15: ='All Seasons'!L96 -> 105.84615 | H15: ='All Seasons'!M96 -> 8 | I15: ='All Seasons'!N96 -> 10 | J15: =IF('All Seasons'!O96=1,"YES","-") -> -
A16: ='All Seasons'!B97 -> 12 | B16: ='All Seasons'!C97 -> Vandalay Industries | C16: ='All Seasons'!D97 -> John | D16: ='All Seasons'!I97 -> 10-3-0 | E16: ='All Seasons'!J97 -> 0.76923077 | F16: ='All Seasons'!K97 -> 1516 | G16: ='All Seasons'!L97 -> 116.61538 | H16: ='All Seasons'!M97 -> 4 | I16: ='All Seasons'!N97 -> 3 | J16: =IF('All Seasons'!O97=1,"YES","-") -> YES
B17: League total / average | E17: =AVERAGE(E5:E16) -> 0.5 | F17: =SUM(F5:F16) -> 16916 | G17: =AVERAGE(G5:G16) -> 108.4359
A19: Correlation with draft slot (this season)
A20: Win % | C20: =CORREL($A$5:$A$16,E5:E16) -> 0.23521144
A21: Pts/Game | C21: =CORREL($A$5:$A$16,G5:G16) -> -0.21014898
A22: PF Rank (1=most pts) | C22: =CORREL($A$5:$A$16,H5:H16) -> 0.21678322
A23: Final Finish (1=champ) | C23: =CORREL($A$5:$A$16,I5:I16) -> 0.13286713
A24: Negative on Win % / Pts-Game = earlier picks did better. Positive on PF Rank / Final Finish = earlier picks did better.

Sheet Season 2019
A1: 2019 season — ordered by draft slot
A2: 13-game regular season · 12 teams · 6 playoff spots · pick 1 = first overall
A4: Draft Slot | B4: Team | C4: Manager | D4: Record | E4: Win % | F4: Points For | G4: Pts/Game | H4: PF Rank | I4: Final Finish | J4: Made Playoffs?
A5: ='All Seasons'!B98 -> 1 | B5: ='All Seasons'!C98 -> Donkey Punchers | C5: ='All Seasons'!D98 -> Barrett | D5: ='All Seasons'!I98 -> 4-9-0 | E5: ='All Seasons'!J98 -> 0.30769231 | F5: ='All Seasons'!K98 -> 1066.54 | G5: ='All Seasons'!L98 -> 82.041538 | H5: ='All Seasons'!M98 -> 12 | I5: ='All Seasons'!N98 -> 7 | J5: =IF('All Seasons'!O98=1,"YES","-") -> -
A6: ='All Seasons'!B99 -> 2 | B6: ='All Seasons'!C99 -> RedZone480 | C6: ='All Seasons'!D99 -> Robert | D6: ='All Seasons'!I99 -> 6-7-0 | E6: ='All Seasons'!J99 -> 0.46153846 | F6: ='All Seasons'!K99 -> 1222.48 | G6: ='All Seasons'!L99 -> 94.036923 | H6: ='All Seasons'!M99 -> 9 | I6: ='All Seasons'!N99 -> 11 | J6: =IF('All Seasons'!O99=1,"YES","-") -> -
A7: ='All Seasons'!B100 -> 3 | B7: ='All Seasons'!C100 -> Vandalay Industries | C7: ='All Seasons'!D100 -> John | D7: ='All Seasons'!I100 -> 8-5-0 | E7: ='All Seasons'!J100 -> 0.61538462 | F7: ='All Seasons'!K100 -> 1334.64 | G7: ='All Seasons'!L100 -> 102.66462 | H7: ='All Seasons'!M100 -> 4 | I7: ='All Seasons'!N100 -> 6 | J7: =IF('All Seasons'!O100=1,"YES","-") -> YES
A8: ='All Seasons'!B101 -> 4 | B8: ='All Seasons'!C101 -> AssKickers | C8: ='All Seasons'!D101 -> Rob M | D8: ='All Seasons'!I101 -> 7-6-0 | E8: ='All Seasons'!J101 -> 0.53846154 | F8: ='All Seasons'!K101 -> 1473.5 | G8: ='All Seasons'!L101 -> 113.34615 | H8: ='All Seasons'!M101 -> 1 | I8: ='All Seasons'!N101 -> 5 | J8: =IF('All Seasons'!O101=1,"YES","-") -> YES
A9: ='All Seasons'!B102 -> 5 | B9: ='All Seasons'!C102 -> Fake News | C9: ='All Seasons'!D102 -> Brian C | D9: ='All Seasons'!I102 -> 7-6-0 | E9: ='All Seasons'!J102 -> 0.53846154 | F9: ='All Seasons'!K102 -> 1213.34 | G9: ='All Seasons'!L102 -> 93.333846 | H9: ='All Seasons'!M102 -> 10 | I9: ='All Seasons'!N102 -> 4 | J9: =IF('All Seasons'!O102=1,"YES","-") -> YES
A10: ='All Seasons'!B103 -> 6 | B10: ='All Seasons'!C103 -> #YouToo | C10: ='All Seasons'!D103 -> Keith | D10: ='All Seasons'!I103 -> 6-7-0 | E10: ='All Seasons'!J103 -> 0.46153846 | F10: ='All Seasons'!K103 -> 1260.92 | G10: ='All Seasons'!L103 -> 96.993846 | H10: ='All Seasons'!M103 -> 6 | I10: ='All Seasons'!N103 -> 9 | J10: =IF('All Seasons'!O103=1,"YES","-") -> -
A11: ='All Seasons'!B104 -> 7 | B11: ='All Seasons'!C104 -> Fournetflix n Chill | C11: ='All Seasons'!D104 -> Cory | D11: ='All Seasons'!I104 -> 4-9-0 | E11: ='All Seasons'!J104 -> 0.30769231 | F11: ='All Seasons'!K104 -> 1234.78 | G11: ='All Seasons'!L104 -> 94.983077 | H11: ='All Seasons'!M104 -> 8 | I11: ='All Seasons'!N104 -> 8 | J11: =IF('All Seasons'!O104=1,"YES","-") -> -
A12: ='All Seasons'!B105 -> 8 | B12: ='All Seasons'!C105 -> RedNecks | C12: ='All Seasons'!D105 -> Jim | D12: ='All Seasons'!I105 -> 9-4-0 | E12: ='All Seasons'!J105 -> 0.69230769 | F12: ='All Seasons'!K105 -> 1457.84 | G12: ='All Seasons'!L105 -> 112.14154 | H12: ='All Seasons'!M105 -> 2 | I12: ='All Seasons'!N105 -> 1 | J12: =IF('All Seasons'!O105=1,"YES","-") -> YES
A13: ='All Seasons'!B106 -> 9 | B13: ='All Seasons'!C106 -> Spike's Chupacabras | C13: ='All Seasons'!D106 -> Spike | D13: ='All Seasons'!I106 -> 7-6-0 | E13: ='All Seasons'!J106 -> 0.53846154 | F13: ='All Seasons'!K106 -> 1322.48 | G13: ='All Seasons'!L106 -> 101.72923 | H13: ='All Seasons'!M106 -> 5 | I13: ='All Seasons'!N106 -> 3 | J13: =IF('All Seasons'!O106=1,"YES","-") -> YES
A14: ='All Seasons'!B107 -> 10 | B14: ='All Seasons'!C107 -> Going Postal | C14: ='All Seasons'!D107 -> Steve | D14: ='All Seasons'!I107 -> 9-4-0 | E14: ='All Seasons'!J107 -> 0.69230769 | F14: ='All Seasons'!K107 -> 1414.44 | G14: ='All Seasons'!L107 -> 108.80308 | H14: ='All Seasons'!M107 -> 3 | I14: ='All Seasons'!N107 -> 2 | J14: =IF('All Seasons'!O107=1,"YES","-") -> YES
A15: ='All Seasons'!B108 -> 11 | B15: ='All Seasons'!C108 -> Closer | C15: ='All Seasons'!D108 -> Rick | D15: ='All Seasons'!I108 -> 5-8-0 | E15: ='All Seasons'!J108 -> 0.38461538 | F15: ='All Seasons'!K108 -> 1152.28 | G15: ='All Seasons'!L108 -> 88.636923 | H15: ='All Seasons'!M108 -> 11 | I15: ='All Seasons'!N108 -> 12 | J15: =IF('All Seasons'!O108=1,"YES","-") -> -
A16: ='All Seasons'!B109 -> 12 | B16: ='All Seasons'!C109 -> Scott's Scabs | C16: ='All Seasons'!D109 -> Scott | D16: ='All Seasons'!I109 -> 6-7-0 | E16: ='All Seasons'!J109 -> 0.46153846 | F16: ='All Seasons'!K109 -> 1249.78 | G16: ='All Seasons'!L109 -> 96.136923 | H16: ='All Seasons'!M109 -> 7 | I16: ='All Seasons'!N109 -> 10 | J16: =IF('All Seasons'!O109=1,"YES","-") -> -
B17: League total / average | E17: =AVERAGE(E5:E16) -> 0.5 | F17: =SUM(F5:F16) -> 15403.02 | G17: =AVERAGE(G5:G16) -> 98.737308
A19: Correlation with draft slot (this season)
A20: Win % | C20: =CORREL($A$5:$A$16,E5:E16) -> 0.1802322
A21: Pts/Game | C21: =CORREL($A$5:$A$16,G5:G16) -> 0.19518869
A22: PF Rank (1=most pts) | C22: =CORREL($A$5:$A$16,H5:H16) -> -0.16083916
A23: Final Finish (1=champ) | C23: =CORREL($A$5:$A$16,I5:I16) -> -0.020979021
A24: Negative on Win % / Pts-Game = earlier picks did better. Positive on PF Rank / Final Finish = earlier picks did better.

Sheet Season 2020
A1: 2020 season — ordered by draft slot
A2: 13-game regular season · 12 teams · 6 playoff spots · pick 1 = first overall
A4: Draft Slot | B4: Team | C4: Manager | D4: Record | E4: Win % | F4: Points For | G4: Pts/Game | H4: PF Rank | I4: Final Finish | J4: Made Playoffs?
A5: ='All Seasons'!B110 -> 1 | B5: ='All Seasons'!C110 -> Donkey Punchers | C5: ='All Seasons'!D110 -> Barrett | D5: ='All Seasons'!I110 -> 5-8-0 | E5: ='All Seasons'!J110 -> 0.38461538 | F5: ='All Seasons'!K110 -> 1322.86 | G5: ='All Seasons'!L110 -> 101.75846 | H5: ='All Seasons'!M110 -> 10 | I5: ='All Seasons'!N110 -> 12 | J5: =IF('All Seasons'!O110=1,"YES","-") -> -
A6: ='All Seasons'!B111 -> 2 | B6: ='All Seasons'!C111 -> Vandalay Industries | C6: ='All Seasons'!D111 -> John | D6: ='All Seasons'!I111 -> 4-9-0 | E6: ='All Seasons'!J111 -> 0.30769231 | F6: ='All Seasons'!K111 -> 1195.64 | G6: ='All Seasons'!L111 -> 91.972308 | H6: ='All Seasons'!M111 -> 12 | I6: ='All Seasons'!N111 -> 9 | J6: =IF('All Seasons'!O111=1,"YES","-") -> -
A7: ='All Seasons'!B112 -> 3 | B7: ='All Seasons'!C112 -> Yuge Loser(s) | C7: ='All Seasons'!D112 -> Brian C | D7: ='All Seasons'!I112 -> 7-6-0 | E7: ='All Seasons'!J112 -> 0.53846154 | F7: ='All Seasons'!K112 -> 1420.02 | G7: ='All Seasons'!L112 -> 109.23231 | H7: ='All Seasons'!M112 -> 7 | I7: ='All Seasons'!N112 -> 6 | J7: =IF('All Seasons'!O112=1,"YES","-") -> YES
A8: ='All Seasons'!B113 -> 4 | B8: ='All Seasons'!C113 -> RedNecks | C8: ='All Seasons'!D113 -> Jim | D8: ='All Seasons'!I113 -> 4-9-0 | E8: ='All Seasons'!J113 -> 0.30769231 | F8: ='All Seasons'!K113 -> 1440.48 | G8: ='All Seasons'!L113 -> 110.80615 | H8: ='All Seasons'!M113 -> 6 | I8: ='All Seasons'!N113 -> 8 | J8: =IF('All Seasons'!O113=1,"YES","-") -> -
A9: ='All Seasons'!B114 -> 5 | B9: ='All Seasons'!C114 -> Dark Shadows | C9: ='All Seasons'!D114 -> Cory | D9: ='All Seasons'!I114 -> 8-5-0 | E9: ='All Seasons'!J114 -> 0.61538462 | F9: ='All Seasons'!K114 -> 1522.88 | G9: ='All Seasons'!L114 -> 117.14462 | H9: ='All Seasons'!M114 -> 2 | I9: ='All Seasons'!N114 -> 3 | J9: =IF('All Seasons'!O114=1,"YES","-") -> YES
A10: ='All Seasons'!B115 -> 6 | B10: ='All Seasons'!C115 -> #YouToo | C10: ='All Seasons'!D115 -> Keith | D10: ='All Seasons'!I115 -> 7-6-0 | E10: ='All Seasons'!J115 -> 0.53846154 | F10: ='All Seasons'!K115 -> 1558.02 | G10: ='All Seasons'!L115 -> 119.84769 | H10: ='All Seasons'!M115 -> 1 | I10: ='All Seasons'!N115 -> 1 | J10: =IF('All Seasons'!O115=1,"YES","-") -> YES
A11: ='All Seasons'!B116 -> 7 | B11: ='All Seasons'!C116 -> AssKickers | C11: ='All Seasons'!D116 -> Rob M | D11: ='All Seasons'!I116 -> 6-7-0 | E11: ='All Seasons'!J116 -> 0.46153846 | F11: ='All Seasons'!K116 -> 1501 | G11: ='All Seasons'!L116 -> 115.46154 | H11: ='All Seasons'!M116 -> 3 | I11: ='All Seasons'!N116 -> 7 | J11: =IF('All Seasons'!O116=1,"YES","-") -> -
A12: ='All Seasons'!B117 -> 8 | B12: ='All Seasons'!C117 -> Going Postal | C12: ='All Seasons'!D117 -> Steve | D12: ='All Seasons'!I117 -> 5-8-0 | E12: ='All Seasons'!J117 -> 0.38461538 | F12: ='All Seasons'!K117 -> 1245.38 | G12: ='All Seasons'!L117 -> 95.798462 | H12: ='All Seasons'!M117 -> 11 | I12: ='All Seasons'!N117 -> 11 | J12: =IF('All Seasons'!O117=1,"YES","-") -> -
A13: ='All Seasons'!B118 -> 9 | B13: ='All Seasons'!C118 -> Closer | C13: ='All Seasons'!D118 -> Rick | D13: ='All Seasons'!I118 -> 7-6-0 | E13: ='All Seasons'!J118 -> 0.53846154 | F13: ='All Seasons'!K118 -> 1415.36 | G13: ='All Seasons'!L118 -> 108.87385 | H13: ='All Seasons'!M118 -> 9 | I13: ='All Seasons'!N118 -> 2 | J13: =IF('All Seasons'!O118=1,"YES","-") -> YES
A14: ='All Seasons'!B119 -> 10 | B14: ='All Seasons'!C119 -> RedZone480 | C14: ='All Seasons'!D119 -> Robert | D14: ='All Seasons'!I119 -> 6-7-0 | E14: ='All Seasons'!J119 -> 0.46153846 | F14: ='All Seasons'!K119 -> 1418.68 | G14: ='All Seasons'!L119 -> 109.12923 | H14: ='All Seasons'!M119 -> 8 | I14: ='All Seasons'!N119 -> 10 | J14: =IF('All Seasons'!O119=1,"YES","-") -> -
A15: ='All Seasons'!B120 -> 11 | B15: ='All Seasons'!C120 -> Scott's Scabs | C15: ='All Seasons'!D120 -> Scott | D15: ='All Seasons'!I120 -> 8-5-0 | E15: ='All Seasons'!J120 -> 0.61538462 | F15: ='All Seasons'!K120 -> 1482.78 | G15: ='All Seasons'!L120 -> 114.06 | H15: ='All Seasons'!M120 -> 4 | I15: ='All Seasons'!N120 -> 5 | J15: =IF('All Seasons'!O120=1,"YES","-") -> YES
A16: ='All Seasons'!B121 -> 12 | B16: ='All Seasons'!C121 -> Spike's Chupacabras | C16: ='All Seasons'!D121 -> Spike | D16: ='All Seasons'!I121 -> 11-2-0 | E16: ='All Seasons'!J121 -> 0.84615385 | F16: ='All Seasons'!K121 -> 1450.4 | G16: ='All Seasons'!L121 -> 111.56923 | H16: ='All Seasons'!M121 -> 5 | I16: ='All Seasons'!N121 -> 4 | J16: =IF('All Seasons'!O121=1,"YES","-") -> YES
